Workbook

Sheet KPI_Catalog
A1: Business Questions & KPI Catalog
A2: Working catalog linking business questions to KPI definitions, calculation logic, required data, expected sources, future Gold datasets, and dashboard pages. Source fields remain provisional until Data Source Assessment.
A4: KPI_ID | B4: Domain | C4: Business_Question | D4: KPI_Name | E4: Business_Definition | F4: Calculation_Logic | G4: Unit | H4: Granularity | I4: Dimensions | J4: Required_Data | K4: Expected_Source | L4: Gold_Dataset | M4: Dashboard_Page | N4: Priority | O4: Validation_Status | P4: Notes
A5: INF-001 | B5: Inflation & CPI | C5: How is inflation evolving in the Dominican Republic? | D5: CPI Index | E5: Official consumer price index level for the reference period. | F5: Published CPI index value | G5: Index | H5: Monthly | I5: Date; Expenditure Group | J5: CPI index; reference period | K5: BCRD — IPC base Oct 2019–Sep 2020 workbooks (validated 2026-10-23) | L5: gold.inflation_metrics | M5: Inflation & CPI | N5: MVP | O5: Validated | P5: Base Oct 2019 - Sep 2020 = 100. Series: headline 1984+, groups 1999+, core 2000+, regions 2011+. gold.inflation_metrics.
A6: INF-002 | B6: Inflation & CPI | C6: How is inflation evolving in the Dominican Republic? | D6: Monthly Inflation | E6: Percentage change in CPI versus the previous month. | F6: (CPI_t / CPI_t-1 - 1) * 100 | G6: % | H6: Monthly | I6: Date | J6: Current CPI; previous-month CPI | K6: BCRD — IPC base Oct 2019–Sep 2020 workbooks (validated 2026-10-23) | L6: gold.inflation_metrics | M6: Inflation & CPI | N6: MVP | O6: Validated | P6: Calculated from the index; reconciles with BCRD published monthly variation on 5,550/5,550 comparable values (all series).
A7: INF-003 | B7: Inflation & CPI | C7: How is inflation evolving in the Dominican Republic? | D7: YoY Inflation | E7: Percentage change in CPI versus the same month one year earlier. | F7: (CPI_t / CPI_t-12 - 1) * 100 | G7: % | H7: Monthly | I7: Date | J7: Current CPI; CPI 12 months prior | K7: BCRD — IPC base Oct 2019–Sep 2020 workbooks (validated 2026-10-23) | L7: gold.inflation_metrics | M7: Inflation & CPI | N7: MVP | O7: Validated | P7: Reconciles with BCRD published 12-month variation (headline and core, 808/808). NULL until 12 months of history (D4 rule).
A8: INF-004 | B8: Inflation & CPI | C8: How is inflation evolving in the Dominican Republic? | D8: YTD Inflation | E8: Cumulative CPI change from the end of the prior year to the current period. | F8: (CPI_t / CPI_Dec_prev_year - 1) * 100 | G8: % | H8: Monthly | I8: Date | J8: Current CPI; prior December CPI | K8: BCRD — IPC base Oct 2019–Sep 2020 workbooks (validated 2026-10-23) | L8: gold.inflation_metrics | M8: Inflation & CPI | N8: MVP | O8: Validated | P8: Equals BCRD "con Dic." variation; reconciles 808/808. NULL in the first year of each series.
A9: INF-005 | B9: Inflation & CPI | C9: How is underlying inflation evolving? | D9: Core Inflation | E9: Underlying inflation measure excluding or adjusting selected volatile components according to the official methodology. | F9: Same formulas applied to the official BCRD core CPI index | G9: % | H9: Monthly | I9: Date | J9: Official core inflation series | K9: BCRD — IPC base Oct 2019–Sep 2020 workbooks (validated 2026-10-23) | L9: gold.inflation_metrics | M9: Inflation & CPI | N9: MVP | O9: Validated | P9: Official core index used as published (excludes volatile agricultural goods, alcohol, tobacco, fuels, administered and transport services); series_type = core.
A10: INF-006 | B10: Inflation & CPI | C10: Which expenditure groups are experiencing the greatest price changes? | D10: Inflation by Expenditure Group | E10: Inflation rate by CPI expenditure group/category. | F10: Same formulas applied to each expenditure-group index | G10: % | H10: Monthly | I10: Date; Expenditure Group | J10: CPI by expenditure group | K10: BCRD — IPC base Oct 2019–Sep 2020 workbooks (validated 2026-10-23) | L10: gold.inflation_metrics | M10: Inflation & CPI | N10: MVP | O10: Validated | P10: 12 COICOP-style groups as published by BCRD; series_type = expenditure_group. Regional CPI (4 regions) also available as series_type = region.
A11: FX-001 | B11: Foreign Exchange | C11: How is the Dominican peso performing against the U.S. dollar? | D11: USD/DOP Buy Rate | E11: Reference buying exchange rate for USD against DOP. | F11: Published BCRD buy rate | G11: DOP/USD | H11: Daily (business days) | I11: Date; Currency; Rate Type | J11: Buy rate | K11: BCRD — Histórico diario de tasas (validated 2026-10-23) | L11: gold.exchange_rate_metrics | M11: FX Market | N11: MVP | O11: Validated | P11: Rate = DOP per 1 USD. Source validated: 1,253 business-day observations 2021-09-20 to 2026-09-18; Bronze table bronze.bcrd_exchange_rates_daily.
A12: FX-002 | B12: Foreign Exchange | C12: How is the Dominican peso performing against the U.S. dollar? | D12: USD/DOP Sell Rate | E12: Reference selling exchange rate for USD against DOP. | F12: Published BCRD sell rate | G12: DOP/USD | H12: Daily (business days) | I12: Date; Currency; Rate Type | J12: Sell rate | K12: BCRD — Histórico diario de tasas (validated 2026-10-23) | L12: gold.exchange_rate_metrics | M12: FX Market | N12: MVP | O12: Validated | P12: Rate = DOP per 1 USD. Same source and coverage as FX-001.
A13: FX-003 | B13: Foreign Exchange | C13: How is the Dominican peso performing against the U.S. dollar? | D13: Daily FX Change | E13: Percentage change versus the prior available trading/observation day. | F13: (Rate_t / Rate_prev_business_day - 1) * 100 | G13: % | H13: Daily (business days) | I13: Date; Currency; Rate Type | J13: Current and prior rate | K13: BCRD — Histórico diario de tasas (validated 2026-10-23) | L13: gold.exchange_rate_metrics | M13: FX Market | N13: MVP | O13: Validated | P13: D1 Methodology: conventional % change (positive = rate up = DOP depreciation). BCRD official apre/depre uses the reciprocal (1/rate), opposite sign; kept as separate reference column, never mixed. Label: "Rate up = peso depreciation".
A14: FX-004 | B14: Foreign Exchange | C14: How is the Dominican peso performing against the U.S. dollar? | D14: MoM FX Change | E14: Percentage change versus comparable prior-month reference. | F14: (Rate_month_end / Rate_prev_month_end - 1) * 100 | G14: % | H14: Monthly | I14: Date; Currency; Rate Type | J14: Current and prior-month rate | K14: BCRD — Histórico diario de tasas (validated 2026-10-23) | L14: gold.exchange_rate_metrics | M14: FX Market | N14: MVP | O14: Validated | P14: D1 conventional % change. D2 Monthly reference = rate on the last available business day of the month. Monthly average may be added later for inflation comparison.
A15: FX-005 | B15: Foreign Exchange | C15: How is the Dominican peso performing against the U.S. dollar? | D15: YoY FX Change | E15: Percentage change versus the comparable period one year earlier. | F15: (Rate_month_end / Rate_month_end_12_months_earlier - 1) * 100 | G15: % | H15: Monthly | I15: Date; Currency; Rate Type | J15: Current and year-ago rate | K15: BCRD — Histórico diario de tasas (validated 2026-10-23) | L15: gold.exchange_rate_metrics | M15: FX Market | N15: MVP | O15: Validated | P15: D1 conventional % change. D2 month-end reference. D4 NULL until 12 months of history exist (first full value Sep-2022); is_full_window flag.
... A19: FX-009 | B19: Foreign Exchange | C19: How is the Dominican peso performing against the U.S. dollar? | D19: 52-Week Low | E19: Lowest exchange rate in the trailing 52-week window. | F19: MIN(rate) over trailing 52 weeks (364 calendar days, current included) | G19: DOP/USD | H19: Daily | I19: Date; Currency; Rate Type | J19: Daily exchange rate history | K19: BCRD — Histórico diario de tasas (validated 2026-10-23) | L19: gold.exchange_rate_metrics | M19: FX Market | N19: MVP | O19: Validated | P19: D4 NULL until 52 weeks of history exist (first full value Sep-2022); is_full_window flag.
A20: MON-001 | B20: Monetary Policy | C20: How has monetary policy evolved relative to inflation? | D20: Monetary Policy Rate | E20: Official monetary policy reference rate. | F20: Published rate | G20: % | H20: Monthly / Event-based | I20: Date | J20: Policy rate | K20: BCRD (to validate) | L20: gold.monetary_policy_metrics | M20: Monetary Policy | N20: MVP | O20: Proposed
A21: MON-002 | B21: Monetary Policy | C21: How has monetary policy evolved relative to inflation? | D21: Policy Rate Change | E21: Change in the policy rate from the previous observation, expressed in basis points. | F21: (Rate_t - Rate_t-1) * 100 | G21: Basis Points | H21: Event-based | I21: Date | J21: Current and prior policy rate | K21: BCRD (to validate) | L21: gold.monetary_policy_metrics | M21: Monetary Policy | N21: MVP | O21: Proposed
A22: MON-003 | B22: Monetary Policy | C22: How has monetary policy evolved relative to inflation? | D22: Policy Rate YTD Change | E22: Cumulative policy-rate change versus the final observation of the prior year. | F22: (Rate_t - Rate_last_prev_year) * 100 | G22: Basis Points | H22: Monthly / Event-based | I22: Date | J22: Current and prior-year-end policy rate | K22: BCRD (to validate) | L22: gold.monetary_policy_metrics | M22: Monetary Policy | N22: MVP | O22: Proposed
A23: MON-004 | B23: Monetary Policy | C23: How has monetary policy evolved relative to inflation? | D23: Inflation–Policy Rate Spread | E23: Difference between the policy rate and YoY inflation. | F23: Policy Rate - YoY Inflation | G23: Percentage Points | H23: Monthly | I23: Date | J23: Policy rate; YoY inflation | K23: BCRD (to validate) | L23: gold.monetary_policy_metrics | M23: Monetary Policy | N23: MVP | O23: Proposed
A24: MON-005 | B24: Monetary Policy | C24: How has monetary policy evolved relative to inflation? | D24: Real Policy Rate Proxy | E24: Simple ex-post proxy for the policy rate adjusted by YoY inflation. | F24: Policy Rate - YoY Inflation | G24: % / Percentage Points | H24: Monthly | I24: Date | J24: Policy rate; YoY inflation | K24: BCRD (to validate) | L24: gold.monetary_policy_metrics | M24: Monetary Policy | N24: MVP | O24: Proposed | P24: Label explicitly as a proxy; not a full expected real-rate measure.
A25: FUEL-001 | B25: Fuel Market | C25: How are fuel prices evolving in the Dominican Republic? | D25: Current Fuel Price | E25: Latest observed official/reference retail fuel price. | F25: Latest available price | G25: DOP/gallon | H25: Weekly | I25: Price week; Fuel type | J25: Fuel type; date; price; unit | K25: MICM — precios-de-combustibles-2010-2026 XLSX (validated 2026-10-23) | L25: gold.fuel_price_metrics | M25: Fuel & Oil Market | N25: MVP | O25: Validated | P25: XLSX authoritative (CSV = XLSX rounded to whole pesos). Zero = not published.
A26: FUEL-002 | B26: Fuel Market | C26: How are fuel prices evolving in the Dominican Republic? | D26: Previous Week Price | E26: Fuel price from the prior weekly observation. | F26: Prior weekly price | G26: DOP/gallon | H26: Weekly | I26: Price week; Fuel type | J26: Fuel type; date; price; unit | K26: MICM — precios-de-combustibles-2010-2026 XLSX (validated 2026-10-23) | L26: gold.fuel_price_metrics | M26: Fuel & Oil Market | N26: MVP | O26: Validated | P26: XLSX authoritative (CSV = XLSX rounded to whole pesos). Zero = not published.
A27: FUEL-003 | B27: Fuel Market | C27: How are fuel prices evolving in the Dominican Republic? | D27: Weekly Price Change | E27: Absolute change versus previous week. | F27: Price_t - Price_t-1 | G27: DOP/gallon | H27: Weekly | I27: Price week; Fuel type | J27: Fuel type; date; price; unit | K27: MICM — precios-de-combustibles-2010-2026 XLSX (validated 2026-10-23) | L27: gold.fuel_price_metrics | M27: Fuel & Oil Market | N27: MVP | O27: Validated | P27: XLSX authoritative (CSV = XLSX rounded to whole pesos). Zero = not published.
A28: FUEL-004 | B28: Fuel Market | C28: How are fuel prices evolving in the Dominican Republic? | D28: Weekly Price Change % | E28: Percentage change versus previous week. | F28: (Price_t / Price_t-1 - 1) * 100 | G28: % | H28: Weekly | I28: Price week; Fuel type | J28: Fuel type; date; price; unit | K28: MICM — precios-de-combustibles-2010-2026 XLSX (validated 2026-10-23) | L28: gold.fuel_price_metrics | M28: Fuel & Oil Market | N28: MVP | O28: Validated | P28: XLSX authoritative (CSV = XLSX rounded to whole pesos). Zero = not published.
A29: FUEL-005 | B29: Fuel Market | C29: How are fuel prices evolving in the Dominican Republic? | D29: Monthly Price Change % | E29: Percentage change versus comparable prior-month price. | F29: (Price_t / Price_prev_month - 1) * 100 | G29: % | H29: Weekly | I29: Price week; Fuel type | J29: Fuel type; date; price; unit | K29: MICM — precios-de-combustibles-2010-2026 XLSX (validated 2026-10-23) | L29: gold.fuel_price_metrics | M29: Fuel & Oil Market | N29: MVP | O29: Validated | P29: XLSX authoritative (CSV = XLSX rounded to whole pesos). Zero = not published. vs last published week of the previous month.
A30: FUEL-006 | B30: Fuel Market | C30: How are fuel prices evolving in the Dominican Republic? | D30: YoY Price Change % | E30: Percentage change versus comparable period one year earlier. | F30: (Price_t / Price_t-1year - 1) * 100 | G30: % | H30: Weekly | I30: Price week; Fuel type | J30: Fuel type; date; price; unit | K30: MICM — precios-de-combustibles-2010-2026 XLSX (validated 2026-10-23) | L30: gold.fuel_price_metrics | M30: Fuel & Oil Market | N30: MVP | O30: Validated | P30: XLSX authoritative (CSV = XLSX rounded to whole pesos). Zero = not published. vs the latest week starting 364–371 days earlier; NULL otherwise.
A31: FUEL-007 | B31: Fuel Market | C31: How are fuel prices evolving in the Dominican Republic? | D31: YTD Price Change % | E31: Percentage change versus final observation of prior year. | F31: (Price_t / Price_last_prev_year - 1) * 100 | G31: % | H31: Weekly | I31: Price week; Fuel type | J31: Fuel type; date; price; unit | K31: MICM — precios-de-combustibles-2010-2026 XLSX (validated 2026-10-23) | L31: gold.fuel_price_metrics | M31: Fuel & Oil Market | N31: MVP | O31: Validated | P31: XLSX authoritative (CSV = XLSX rounded to whole pesos). Zero = not published. vs last published week of the previous year.
A32: FUEL-008 | B32: Fuel Market | C32: How are fuel prices evolving in the Dominican Republic? | D32: 4-Week Moving Average | E32: Average price over trailing four weekly observations. | F32: AVG(price) trailing 4 observations | G32: DOP/gallon | H32: Weekly | I32: Price week; Fuel type | J32: Fuel type; date; price; unit | K32: MICM — precios-de-combustibles-2010-2026 XLSX (validated 2026-10-23) | L32: gold.fuel_price_metrics | M32: Fuel & Oil Market | N32: MVP | O32: Validated | P32: XLSX authoritative (CSV = XLSX rounded to whole pesos). Zero = not published. NULL until 4 weeks of history (D4).
A33: FUEL-009 | B33: Fuel Market | C33: How are fuel prices evolving in the Dominican Republic? | D33: 12-Week Moving Average | E33: Average price over trailing twelve weekly observations. | F33: AVG(price) trailing 12 observations | G33: DOP/gallon | H33: Weekly | I33: Price week; Fuel type | J33: Fuel type; date; price; unit | K33: MICM — precios-de-combustibles-2010-2026 XLSX (validated 2026-10-23) | L33: gold.fuel_price_metrics | M33: Fuel & Oil Market | N33: MVP | O33: Validated | P33: XLSX authoritative (CSV = XLSX rounded to whole pesos). Zero = not published. NULL until 12 weeks of history (D4).
A34: FUEL-010 | B34: Fuel Market | C34: How are fuel prices evolving in the Dominican Republic? | D34: 52-Week High | E34: Maximum fuel price in trailing 52 weeks. | F34: MAX(price) trailing 52 weeks | G34: DOP/gallon | H34: Weekly | I34: Price week; Fuel type | J34: Fuel type; date; price; unit | K34: MICM — precios-de-combustibles-2010-2026 XLSX (validated 2026-10-23) | L34: gold.fuel_price_metrics | M34: Fuel & Oil Market | N34: MVP | O34: Validated | P34: XLSX authoritative (CSV = XLSX rounded to whole pesos). Zero = not published. Trailing 364 days; NULL with is_full_window_52w = false until a full year.
A35: FUEL-011 | B35: Fuel Market | C35: How are fuel prices evolving in the Dominican Republic? | D35: 52-Week Low | E35: Minimum fuel price in trailing 52 weeks. | F35: MIN(price) trailing 52 weeks | G35: DOP/gallon | H35: Weekly | I35: Price week; Fuel type | J35: Fuel type; date; price; unit | K35: MICM — precios-de-combustibles-2010-2026 XLSX (validated 2026-10-23) | L35: gold.fuel_price_metrics | M35: Fuel & Oil Market | N35: MVP | O35: Validated | P35: XLSX authoritative (CSV = XLSX rounded to whole pesos). Zero = not published. Trailing 364 days; NULL with is_full_window_52w = false until a full year.
A36: FUEL-012 | B36: Fuel Market | C36: How are fuel prices evolving in the Dominican Republic? | D36: Fuel Price Volatility | E36: Dispersion of periodic fuel-price changes over a defined rolling window. | F36: STDDEV(periodic returns) over configured rolling window | G36: % | H36: Weekly | I36: Price week; Fuel type | J36: Fuel type; date; price; unit | K36: MICM — precios-de-combustibles-2010-2026 XLSX (validated 2026-10-23) | L36: gold.fuel_price_metrics | M36: Fuel & Oil Market | N36: MVP | O36: Validated | P36: XLSX authoritative (CSV = XLSX rounded to whole pesos). Zero = not published. Std. dev. of weekly % changes over the trailing 12 weeks.
A37: OIL-001 | B37: International Oil | C37: How are international oil prices evolving? | D37: WTI Price | E37: Reference WTI crude-oil price. | F37: Published market/reference value | G37: USD/barrel | H37: Daily | I37: Date; Benchmark | J37: Date; benchmark; price | K37: U.S. EIA / reputable market source (to validate) | L37: gold.oil_market_metrics | M37: Fuel & Oil Market | N37: MVP | O37: Proposed
A38: OIL-002 | B38: International Oil | C38: How are international oil prices evolving? | D38: Brent Price | E38: Reference Brent crude-oil price. | F38: Published market/reference value | G38: USD/barrel | H38: Daily | I38: Date; Benchmark | J38: Date; benchmark; price | K38: U.S. EIA / reputable market source (to validate) | L38: gold.oil_market_metrics | M38: Fuel & Oil Market | N38: MVP | O38: Proposed
A39: OIL-003 | B39: International Oil | C39: How are international oil prices evolving? | D39: WTI WoW % | E39: Weekly percentage change in WTI. | F39: (WTI_t / WTI_prev_week - 1) * 100 | G39: % | H39: Daily | I39: Date; Benchmark | J39: Date; benchmark; price | K39: U.S. EIA / reputable market source (to validate) | L39: gold.oil_market_metrics | M39: Fuel & Oil Market | N39: MVP | O39: Proposed
A40: OIL-004 | B40: International Oil | C40: How are international oil prices evolving? | D40: Brent WoW % | E40: Weekly percentage change in Brent. | F40: (Brent_t / Brent_prev_week - 1) * 100 | G40: % | H40: Daily | I40: Date; Benchmark | J40: Date; benchmark; price | K40: U.S. EIA / reputable market source (to validate) | L40: gold.oil_market_metrics | M40: Fuel & Oil Market | N40: MVP | O40: Proposed
A41: OIL-005 | B41: International Oil | C41: How are international oil prices evolving? | D41: WTI MoM % | E41: Monthly percentage change in WTI. | F41: (WTI_t / WTI_prev_month - 1) * 100 | G41: % | H41: Daily | I41: Date; Benchmark | J41: Date; benchmark; price | K41: U.S. EIA / reputable market source (to validate) | L41: gold.oil_market_metrics | M41: Fuel & Oil Market | N41: MVP | O41: Proposed
A42: OIL-006 | B42: International Oil | C42: How are international oil prices evolving? | D42: Brent MoM % | E42: Monthly percentage change in Brent. | F42: (Brent_t / Brent_prev_month - 1) * 100 | G42: % | H42: Daily | I42: Date; Benchmark | J42: Date; benchmark; price | K42: U.S. EIA / reputable market source (to validate) | L42: gold.oil_market_metrics | M42: Fuel & Oil Market | N42: MVP | O42: Proposed
A43: OIL-007 | B43: International Oil | C43: How are international oil prices evolving? | D43: WTI 30-Day Moving Average | E43: Rolling average of WTI prices. | F43: AVG(WTI) trailing 30-day window | G43: USD/barrel | H43: Daily | I43: Date; Benchmark | J43: Date; benchmark; price | K43: U.S. EIA / reputable market source (to validate) | L43: gold.oil_market_metrics | M43: Fuel & Oil Market | N43: MVP | O43: Proposed
A44: OIL-008 | B44: International Oil | C44: How are international oil prices evolving? | D44: Brent 30-Day Moving Average | E44: Rolling average of Brent prices. | F44: AVG(Brent) trailing 30-day window | G44: USD/barrel | H44: Daily | I44: Date; Benchmark | J44: Date; benchmark; price | K44: U.S. EIA / reputable market source (to validate) | L44: gold.oil_market_metrics | M44: Fuel & Oil Market | N44: MVP | O44: Proposed
...

Sheet Business_Questions
A1: Business Questions Register
A2: High-level analytical questions that drive data requirements, KPIs, future Gold datasets, and dashboard design.
A4: Question_ID | B4: Domain | C4: Business_Question | D4: Priority | E4: Validation_Status
A5: BQ-001 | B5: Inflation & CPI | C5: How is inflation evolving in the Dominican Republic? | D5: MVP | E5: Validated
A6: BQ-002 | B6: Inflation & CPI | C6: Which expenditure groups are experiencing the greatest price changes? | D6: MVP | E6: Validated
A7: BQ-003 | B7: Foreign Exchange | C7: How is the Dominican peso performing against the U.S. dollar? | D7: MVP | E7: Validated
A8: BQ-004 | B8: Monetary Policy | C8: How has monetary policy evolved relative to inflation? | D8: MVP | E8: Proposed
A9: BQ-005 | B9: Fuel Market | C9: How are fuel prices evolving in the Dominican Republic? | D9: MVP | E9: Validated
A10: BQ-006 | B10: International Oil | C10: How are international oil prices evolving? | D10: MVP | E10: Proposed
A11: BQ-007 | B11: Economic Relationships | C11: How do international oil prices relate to Dominican fuel prices? | D11: MVP | E11: Proposed
A12: BQ-008 | B12: Consumer / Basic Basket | C12: Which products are contributing most to changes in household purchasing costs? | D12: MVP | E12: Partially Validated
A13: BQ-009 | B13: Agricultural Prices | C13: Which agricultural products have experienced the greatest price changes, volatility, or seasonality? | D13: MVP | E13: Proposed
A14: BQ-010 | B14: Energy / Electricity | C14: How are electricity and energy costs evolving? | D14: Phase 2 | E14: Pending Source Validation
A15: BQ-011 | B15: Housing / Rentals | C15: How are rental prices and housing costs evolving? | D15: Phase 2 | E15: Pending Source Validation
... A17: BQ-013 | B17: Cross-Domain | C17: How is the overall cost-of-living environment changing? | D17: MVP | E17: Validated

Sheet Domain_Summary
A1: Domain Summary
A2: Portfolio-level summary of KPI coverage by analytical domain. Counts are calculated from the KPI Catalog.
A4: Domain | B4: Total KPIs | C4: MVP KPIs | D4: Phase 2 KPIs | E4: Proposed | F4: Pending Source Validation | G4: Primary Dashboard Page
A5: Inflation & CPI | B5: =COUNTIF(KPI_Catalog!$B$5:$B$200,A5) | C5: =COUNTIFS(KPI_Catalog!$B$5:$B$200,A5,KPI_Catalog!$N$5:$N$200,"MVP") | D5: =COUNTIFS(KPI_Catalog!$B$5:$B$200,A5,KPI_Catalog!$N$5:$N$200,"Phase 2") | E5: =COUNTIFS(KPI_Catalog!$B$5:$B$200,A5,KPI_Catalog!$O$5:$O$200,"Proposed") | F5: =COUNTIFS(KPI_Catalog!$B$5:$B$200,A5,KPI_Catalog!$O$5:$O$200,"Pending Source Validation") | G5: Inflation & CPI
A6: Foreign Exchange | B6: =COUNTIF(KPI_Catalog!$B$5:$B$200,A6) | C6: =COUNTIFS(KPI_Catalog!$B$5:$B$200,A6,KPI_Catalog!$N$5:$N$200,"MVP") | D6: =COUNTIFS(KPI_Catalog!$B$5:$B$200,A6,KPI_Catalog!$N$5:$N$200,"Phase 2") | E6: =COUNTIFS(KPI_Catalog!$B$5:$B$200,A6,KPI_Catalog!$O$5:$O$200,"Proposed") | F6: =COUNTIFS(KPI_Catalog!$B$5:$B$200,A6,KPI_Catalog!$O$5:$O$200,"Pending Source Validation") | G6: FX Market
A7: Monetary Policy | B7: =COUNTIF(KPI_Catalog!$B$5:$B$200,A7) | C7: =COUNTIFS(KPI_Catalog!$B$5:$B$200,A7,KPI_Catalog!$N$5:$N$200,"MVP") | D7: =COUNTIFS(KPI_Catalog!$B$5:$B$200,A7,KPI_Catalog!$N$5:$N$200,"Phase 2") | E7: =COUNTIFS(KPI_Catalog!$B$5:$B$200,A7,KPI_Catalog!$O$5:$O$200,"Proposed") | F7: =COUNTIFS(KPI_Catalog!$B$5:$B$200,A7,KPI_Catalog!$O$5:$O$200,"Pending Source Validation") | G7: Monetary Policy
A8: Fuel Market | B8: =COUNTIF(KPI_Catalog!$B$5:$B$200,A8) | C8: =COUNTIFS(KPI_Catalog!$B$5:$B$200,A8,KPI_Catalog!$N$5:$N$200,"MVP") | D8: =COUNTIFS(KPI_Catalog!$B$5:$B$200,A8,KPI_Catalog!$N$5:$N$200,"Phase 2") | E8: =COUNTIFS(KPI_Catalog!$B$5:$B$200,A8,KPI_Catalog!$O$5:$O$200,"Proposed") | F8: =COUNTIFS(KPI_Catalog!$B$5:$B$200,A8,KPI_Catalog!$O$5:$O$200,"Pending Source Validation") | G8: Fuel & Oil Market
A9: International Oil | B9: =COUNTIF(KPI_Catalog!$B$5:$B$200,A9) | C9: =COUNTIFS(KPI_Catalog!$B$5:$B$200,A9,KPI_Catalog!$N$5:$N$200,"MVP") | D9: =COUNTIFS(KPI_Catalog!$B$5:$B$200,A9,KPI_Catalog!$N$5:$N$200,"Phase 2") | E9: =COUNTIFS(KPI_Catalog!$B$5:$B$200,A9,KPI_Catalog!$O$5:$O$200,"Proposed") | F9: =COUNTIFS(KPI_Catalog!$B$5:$B$200,A9,KPI_Catalog!$O$5:$O$200,"Pending Source Validation") | G9: Fuel & Oil Market
A10: Economic Relationships | B10: =COUNTIF(KPI_Catalog!$B$5:$B$200,A10) | C10: =COUNTIFS(KPI_Catalog!$B$5:$B$200,A10,KPI_Catalog!$N$5:$N$200,"MVP") | D10: =COUNTIFS(KPI_Catalog!$B$5:$B$200,A10,KPI_Catalog!$N$5:$N$200,"Phase 2") | E10: =COUNTIFS(KPI_Catalog!$B$5:$B$200,A10,KPI_Catalog!$O$5:$O$200,"Proposed") | F10: =COUNTIFS(KPI_Catalog!$B$5:$B$200,A10,KPI_Catalog!$O$5:$O$200,"Pending Source Validation") | G10: Economic Relationships
A11: Consumer / Basic Basket | B11: =COUNTIF(KPI_Catalog!$B$5:$B$200,A11) | C11: =COUNTIFS(KPI_Catalog!$B$5:$B$200,A11,KPI_Catalog!$N$5:$N$200,"MVP") | D11: =COUNTIFS(KPI_Catalog!$B$5:$B$200,A11,KPI_Catalog!$N$5:$N$200,"Phase 2") | E11: =COUNTIFS(KPI_Catalog!$B$5:$B$200,A11,KPI_Catalog!$O$5:$O$200,"Proposed") | F11: =COUNTIFS(KPI_Catalog!$B$5:$B$200,A11,KPI_Catalog!$O$5:$O$200,"Pending Source Validation") | G11: Basic Basket & Consumer Prices
A12: Agricultural Prices | B12: =COUNTIF(KPI_Catalog!$B$5:$B$200,A12) | C12: =COUNTIFS(KPI_Catalog!$B$5:$B$200,A12,KPI_Catalog!$N$5:$N$200,"MVP") | D12: =COUNTIFS(KPI_Catalog!$B$5:$B$200,A12,KPI_Catalog!$N$5:$N$200,"Phase 2") | E12: =COUNTIFS(KPI_Catalog!$B$5:$B$200,A12,KPI_Catalog!$O$5:$O$200,"Proposed") | F12: =COUNTIFS(KPI_Catalog!$B$5:$B$200,A12,KPI_Catalog!$O$5:$O$200,"Pending Source Validation") | G12: Agricultural Prices
A13: Energy / Electricity | B13: =COUNTIF(KPI_Catalog!$B$5:$B$200,A13) | C13: =COUNTIFS(KPI_Catalog!$B$5:$B$200,A13,KPI_Catalog!$N$5:$N$200,"MVP") | D13: =COUNTIFS(KPI_Catalog!$B$5:$B$200,A13,KPI_Catalog!$N$5:$N$200,"Phase 2") | E13: =COUNTIFS(KPI_Catalog!$B$5:$B$200,A13,KPI_Catalog!$O$5:$O$200,"Proposed") | F13: =COUNTIFS(KPI_Catalog!$B$5:$B$200,A13,KPI_Catalog!$O$5:$O$200,"Pending Source Validation") | G13: Energy & Electricity
A14: Housing / Rentals | B14: =COUNTIF(KPI_Catalog!$B$5:$B$200,A14) | C14: =COUNTIFS(KPI_Catalog!$B$5:$B$200,A14,KPI_Catalog!$N$5:$N$200,"MVP") | D14: =COUNTIFS(KPI_Catalog!$B$5:$B$200,A14,KPI_Catalog!$N$5:$N$200,"Phase 2") | E14: =COUNTIFS(KPI_Catalog!$B$5:$B$200,A14,KPI_Catalog!$O$5:$O$200,"Proposed") | F14: =COUNTIFS(KPI_Catalog!$B$5:$B$200,A14,KPI_Catalog!$O$5:$O$200,"Pending Source Validation") | G14: Housing & Cost of Living
A15: Cost of Living | B15: =COUNTIF(KPI_Catalog!$B$5:$B$200,A15) | C15: =COUNTIFS(KPI_Catalog!$B$5:$B$200,A15,KPI_Catalog!$N$5:$N$200,"MVP") | D15: =COUNTIFS(KPI_Catalog!$B$5:$B$200,A15,KPI_Catalog!$N$5:$N$200,"Phase 2") | E15: =COUNTIFS(KPI_Catalog!$B$5:$B$200,A15,KPI_Catalog!$O$5:$O$200,"Proposed") | F15: =COUNTIFS(KPI_Catalog!$B$5:$B$200,A15,KPI_Catalog!$O$5:$O$200,"Pending Source Validation") | G15: Cost of Living

Sheet Definitions
A1: Catalog Definitions & Governance
A2: Reference definitions for the fields and status values used in the KPI catalog.
A4: Field | B4: Definition | C4: Guidance
A5: KPI_ID | B5: Unique KPI identifier. | C5: Use domain prefix + sequential number (e.g., INF-001).
A6: Domain | B6: Analytical subject area. | C6: Keep domains stable unless scope is formally changed.
A7: Business_Question | B7: Question the KPI helps answer. | C7: Every KPI should trace to a business need/question.
A8: KPI_Name | B8: Short business-friendly metric name. | C8: Prefer terminology that can appear on dashboards.
A9: Business_Definition | B9: Plain-language definition. | C9: Describe meaning before technical calculation.
A10: Calculation_Logic | B10: Proposed formula or derivation. | C10: Must be validated against source definitions and grain.
A11: Unit | B11: Metric unit. | C11: Examples: %, DOP/USD, USD/barrel, Index.
A12: Granularity | B12: Expected observation/analysis frequency. | C12: Examples: daily, weekly, monthly.
A13: Dimensions | B13: Dimensions needed to slice/filter the KPI. | C13: Examples: date, fuel type, region, product.
A14: Required_Data | B14: Minimum fields/series required. | C14: Validated during Data Source Assessment.
A15: Expected_Source | B15: Likely source institution/provider. | C15: Provisional until source assessment is complete.
... A20: Notes | B20: Important caveats or implementation decisions. | C20: Use for comparability, methodology, or scope caveats.
